2023-10-01 12:03:24,025 - ERROR - Ошибка при выполнении запроса: HTTPSConnectionPool(host='zturbo.az', port=443): Max retries exceeded with url: /autos?q%5Bsort%5D=&q%5Bmake%5D%5B%5D=&q%5Bmodel%5D%5B%5D=&q%5Bused%5D=&q%5Bregion%5D%5B%5D=&q%5Bregion%5D%5B%5D=1&q%5Bregion%5D%5B%5D=3&q%5Bprice_from%5D=&q%5Bprice_to%5D=7500&q%5Bcurrency%5D=azn&q%5Bloan%5D=0&q%5Bbarter%5D=0&q%5Bcategory%5D%5B%5D=&q%5Bcategory%5D%5B%5D=14&q%5Bcategory%5D%5B%5D=2&q%5Bcategory%5D%5B%5D=28&q%5Bcategory%5D%5B%5D=5&q%5Bcategory%5D%5B%5D=21&q%5Bcategory%5D%5B%5D=6&q%5Bcategory%5D%5B%5D=22&q%5Bcategory%5D%5B%5D=8&q%5Bcategory%5D%5B%5D=1&q%5Bcategory%5D%5B%5D=4&q%5Byear_from%5D=&q%5Byear_to%5D=&q%5Bcolor%5D%5B%5D=&q%5Bfuel_type%5D%5B%5D=&q%5Bgear%5D%5B%5D=&q%5Btransmission%5D%5B%5D=&q%5Btransmission%5D%5B%5D=2&q%5Btransmission%5D%5B%5D=3&q%5Btransmission%5D%5B%5D=4&q%5Bengine_volume_from%5D=&q%5Bengine_volume_to%5D=&q%5Bpower_from%5D=&q%5Bpower_to%5D=&q%5Bmileage_from%5D=&q%5Bmileage_to%5D=500000&q%5Bonly_shops%5D=&q%5Bprior_owners_count%5D%5B%5D=&q%5Bseats_count%5D%5B%5D=&q%5Bmarket%5D%5B%5D=&q%5Bcrashed%5D=1&q%5Bpainted%5D=1&q%5Bfor_spare_parts%5D=0 (Caused by NameResolutionError("<urllib3.connection.HTTPSConnection object at 0x7f46b5c47130>: Failed to resolve 'zturbo.az' ([Errno -2] Name or service not known)"))
2023-10-01 12:56:54,451 - ERROR - Cause exception while process update id=613471218 by bot id=6113472397
ValidationError: 1 validation error for ReplyKeyboardMarkup
keyboard
  Field required [type=missing, input_value={'resize_keyboard': True}, input_type=dict]
    For further information visit https://errors.pydantic.dev/2.3/v/missing
Traceback (most recent call last):
  File "/home/zaur/Документы/turbo.az/Bina_Az_Bot/venv/lib/python3.10/site-packages/aiogram/dispatcher/dispatcher.py", line 308, in _process_update
    response = await self.feed_update(bot, update, **kwargs)
  File "/home/zaur/Документы/turbo.az/Bina_Az_Bot/venv/lib/python3.10/site-packages/aiogram/dispatcher/dispatcher.py", line 157, in feed_update
    response = await self.update.wrap_outer_middleware(
  File "/home/zaur/Документы/turbo.az/Bina_Az_Bot/venv/lib/python3.10/site-packages/aiogram/dispatcher/middlewares/error.py", line 25, in __call__
    return await handler(event, data)
  File "/home/zaur/Документы/turbo.az/Bina_Az_Bot/venv/lib/python3.10/site-packages/aiogram/dispatcher/middlewares/user_context.py", line 27, in __call__
    return await handler(event, data)
  File "/home/zaur/Документы/turbo.az/Bina_Az_Bot/venv/lib/python3.10/site-packages/aiogram/fsm/middleware.py", line 41, in __call__
    return await handler(event, data)
  File "/home/zaur/Документы/turbo.az/Bina_Az_Bot/venv/lib/python3.10/site-packages/aiogram/dispatcher/event/telegram.py", line 120, in trigger
    return await wrapped_inner(event, kwargs)
  File "/home/zaur/Документы/turbo.az/Bina_Az_Bot/venv/lib/python3.10/site-packages/aiogram/dispatcher/event/handler.py", line 42, in call
    return await wrapped()
  File "/home/zaur/Документы/turbo.az/Bina_Az_Bot/venv/lib/python3.10/site-packages/aiogram/dispatcher/dispatcher.py", line 275, in _listen_update
    return await self.propagate_event(update_type=update_type, event=event, **kwargs)
  File "/home/zaur/Документы/turbo.az/Bina_Az_Bot/venv/lib/python3.10/site-packages/aiogram/dispatcher/router.py", line 116, in propagate_event
    return await observer.wrap_outer_middleware(_wrapped, event=event, data=kwargs)
  File "/home/zaur/Документы/turbo.az/Bina_Az_Bot/venv/lib/python3.10/site-packages/aiogram/dispatcher/router.py", line 111, in _wrapped
    return await self._propagate_event(
  File "/home/zaur/Документы/turbo.az/Bina_Az_Bot/venv/lib/python3.10/site-packages/aiogram/dispatcher/router.py", line 136, in _propagate_event
    response = await observer.trigger(event, **kwargs)
  File "/home/zaur/Документы/turbo.az/Bina_Az_Bot/venv/lib/python3.10/site-packages/aiogram/dispatcher/event/telegram.py", line 120, in trigger
    return await wrapped_inner(event, kwargs)
  File "/home/zaur/Документы/turbo.az/Bina_Az_Bot/venv/lib/python3.10/site-packages/aiogram/dispatcher/event/handler.py", line 42, in call
    return await wrapped()
  File "/home/zaur/Документы/turbo.az/Bina_Az_Bot/bot.py", line 19, in command_start_handler
    keyboard = types.ReplyKeyboardMarkup(resize_keyboard=True)
  File "/home/zaur/Документы/turbo.az/Bina_Az_Bot/venv/lib/python3.10/site-packages/pydantic/main.py", line 165, in __init__
    __pydantic_self__.__pydantic_validator__.validate_python(data, self_instance=__pydantic_self__)
pydantic_core._pydantic_core.ValidationError: 1 validation error for ReplyKeyboardMarkup
keyboard
  Field required [type=missing, input_value={'resize_keyboard': True}, input_type=dict]
    For further information visit https://errors.pydantic.dev/2.3/v/missing
2023-10-01 12:57:04,448 - ERROR - Cause exception while process update id=613471219 by bot id=6113472397
ValidationError: 1 validation error for ReplyKeyboardMarkup
keyboard
  Field required [type=missing, input_value={'resize_keyboard': True}, input_type=dict]
    For further information visit https://errors.pydantic.dev/2.3/v/missing
Traceback (most recent call last):
  File "/home/zaur/Документы/turbo.az/Bina_Az_Bot/venv/lib/python3.10/site-packages/aiogram/dispatcher/dispatcher.py", line 308, in _process_update
    response = await self.feed_update(bot, update, **kwargs)
  File "/home/zaur/Документы/turbo.az/Bina_Az_Bot/venv/lib/python3.10/site-packages/aiogram/dispatcher/dispatcher.py", line 157, in feed_update
    response = await self.update.wrap_outer_middleware(
  File "/home/zaur/Документы/turbo.az/Bina_Az_Bot/venv/lib/python3.10/site-packages/aiogram/dispatcher/middlewares/error.py", line 25, in __call__
    return await handler(event, data)
  File "/home/zaur/Документы/turbo.az/Bina_Az_Bot/venv/lib/python3.10/site-packages/aiogram/dispatcher/middlewares/user_context.py", line 27, in __call__
    return await handler(event, data)
  File "/home/zaur/Документы/turbo.az/Bina_Az_Bot/venv/lib/python3.10/site-packages/aiogram/fsm/middleware.py", line 41, in __call__
    return await handler(event, data)
  File "/home/zaur/Документы/turbo.az/Bina_Az_Bot/venv/lib/python3.10/site-packages/aiogram/dispatcher/event/telegram.py", line 120, in trigger
    return await wrapped_inner(event, kwargs)
  File "/home/zaur/Документы/turbo.az/Bina_Az_Bot/venv/lib/python3.10/site-packages/aiogram/dispatcher/event/handler.py", line 42, in call
    return await wrapped()
  File "/home/zaur/Документы/turbo.az/Bina_Az_Bot/venv/lib/python3.10/site-packages/aiogram/dispatcher/dispatcher.py", line 275, in _listen_update
    return await self.propagate_event(update_type=update_type, event=event, **kwargs)
  File "/home/zaur/Документы/turbo.az/Bina_Az_Bot/venv/lib/python3.10/site-packages/aiogram/dispatcher/router.py", line 116, in propagate_event
    return await observer.wrap_outer_middleware(_wrapped, event=event, data=kwargs)
  File "/home/zaur/Документы/turbo.az/Bina_Az_Bot/venv/lib/python3.10/site-packages/aiogram/dispatcher/router.py", line 111, in _wrapped
    return await self._propagate_event(
  File "/home/zaur/Документы/turbo.az/Bina_Az_Bot/venv/lib/python3.10/site-packages/aiogram/dispatcher/router.py", line 136, in _propagate_event
    response = await observer.trigger(event, **kwargs)
  File "/home/zaur/Документы/turbo.az/Bina_Az_Bot/venv/lib/python3.10/site-packages/aiogram/dispatcher/event/telegram.py", line 120, in trigger
    return await wrapped_inner(event, kwargs)
  File "/home/zaur/Документы/turbo.az/Bina_Az_Bot/venv/lib/python3.10/site-packages/aiogram/dispatcher/event/handler.py", line 42, in call
    return await wrapped()
  File "/home/zaur/Документы/turbo.az/Bina_Az_Bot/bot.py", line 19, in command_start_handler
    keyboard = types.ReplyKeyboardMarkup(resize_keyboard=True)
  File "/home/zaur/Документы/turbo.az/Bina_Az_Bot/venv/lib/python3.10/site-packages/pydantic/main.py", line 165, in __init__
    __pydantic_self__.__pydantic_validator__.validate_python(data, self_instance=__pydantic_self__)
pydantic_core._pydantic_core.ValidationError: 1 validation error for ReplyKeyboardMarkup
keyboard
  Field required [type=missing, input_value={'resize_keyboard': True}, input_type=dict]
    For further information visit https://errors.pydantic.dev/2.3/v/missing
2023-10-01 12:57:38,821 - ERROR - Cause exception while process update id=613471220 by bot id=6113472397
ValidationError: 1 validation error for ReplyKeyboardMarkup
keyboard
  Field required [type=missing, input_value={'resize_keyboard': True}, input_type=dict]
    For further information visit https://errors.pydantic.dev/2.3/v/missing
Traceback (most recent call last):
  File "/home/zaur/Документы/turbo.az/Bina_Az_Bot/venv/lib/python3.10/site-packages/aiogram/dispatcher/dispatcher.py", line 308, in _process_update
    response = await self.feed_update(bot, update, **kwargs)
  File "/home/zaur/Документы/turbo.az/Bina_Az_Bot/venv/lib/python3.10/site-packages/aiogram/dispatcher/dispatcher.py", line 157, in feed_update
    response = await self.update.wrap_outer_middleware(
  File "/home/zaur/Документы/turbo.az/Bina_Az_Bot/venv/lib/python3.10/site-packages/aiogram/dispatcher/middlewares/error.py", line 25, in __call__
    return await handler(event, data)
  File "/home/zaur/Документы/turbo.az/Bina_Az_Bot/venv/lib/python3.10/site-packages/aiogram/dispatcher/middlewares/user_context.py", line 27, in __call__
    return await handler(event, data)
  File "/home/zaur/Документы/turbo.az/Bina_Az_Bot/venv/lib/python3.10/site-packages/aiogram/fsm/middleware.py", line 41, in __call__
    return await handler(event, data)
  File "/home/zaur/Документы/turbo.az/Bina_Az_Bot/venv/lib/python3.10/site-packages/aiogram/dispatcher/event/telegram.py", line 120, in trigger
    return await wrapped_inner(event, kwargs)
  File "/home/zaur/Документы/turbo.az/Bina_Az_Bot/venv/lib/python3.10/site-packages/aiogram/dispatcher/event/handler.py", line 42, in call
    return await wrapped()
  File "/home/zaur/Документы/turbo.az/Bina_Az_Bot/venv/lib/python3.10/site-packages/aiogram/dispatcher/dispatcher.py", line 275, in _listen_update
    return await self.propagate_event(update_type=update_type, event=event, **kwargs)
  File "/home/zaur/Документы/turbo.az/Bina_Az_Bot/venv/lib/python3.10/site-packages/aiogram/dispatcher/router.py", line 116, in propagate_event
    return await observer.wrap_outer_middleware(_wrapped, event=event, data=kwargs)
  File "/home/zaur/Документы/turbo.az/Bina_Az_Bot/venv/lib/python3.10/site-packages/aiogram/dispatcher/router.py", line 111, in _wrapped
    return await self._propagate_event(
  File "/home/zaur/Документы/turbo.az/Bina_Az_Bot/venv/lib/python3.10/site-packages/aiogram/dispatcher/router.py", line 136, in _propagate_event
    response = await observer.trigger(event, **kwargs)
  File "/home/zaur/Документы/turbo.az/Bina_Az_Bot/venv/lib/python3.10/site-packages/aiogram/dispatcher/event/telegram.py", line 120, in trigger
    return await wrapped_inner(event, kwargs)
  File "/home/zaur/Документы/turbo.az/Bina_Az_Bot/venv/lib/python3.10/site-packages/aiogram/dispatcher/event/handler.py", line 42, in call
    return await wrapped()
  File "/home/zaur/Документы/turbo.az/Bina_Az_Bot/bot.py", line 19, in command_start_handler
    keyboard = types.ReplyKeyboardMarkup(resize_keyboard=True)
  File "/home/zaur/Документы/turbo.az/Bina_Az_Bot/venv/lib/python3.10/site-packages/pydantic/main.py", line 165, in __init__
    __pydantic_self__.__pydantic_validator__.validate_python(data, self_instance=__pydantic_self__)
pydantic_core._pydantic_core.ValidationError: 1 validation error for ReplyKeyboardMarkup
keyboard
  Field required [type=missing, input_value={'resize_keyboard': True}, input_type=dict]
    For further information visit https://errors.pydantic.dev/2.3/v/missing
2023-10-01 12:58:14,031 - ERROR - Cause exception while process update id=613471222 by bot id=6113472397
UnboundLocalError: local variable 'keyboard' referenced before assignment
Traceback (most recent call last):
  File "/home/zaur/Документы/turbo.az/Bina_Az_Bot/venv/lib/python3.10/site-packages/aiogram/dispatcher/dispatcher.py", line 308, in _process_update
    response = await self.feed_update(bot, update, **kwargs)
  File "/home/zaur/Документы/turbo.az/Bina_Az_Bot/venv/lib/python3.10/site-packages/aiogram/dispatcher/dispatcher.py", line 157, in feed_update
    response = await self.update.wrap_outer_middleware(
  File "/home/zaur/Документы/turbo.az/Bina_Az_Bot/venv/lib/python3.10/site-packages/aiogram/dispatcher/middlewares/error.py", line 25, in __call__
    return await handler(event, data)
  File "/home/zaur/Документы/turbo.az/Bina_Az_Bot/venv/lib/python3.10/site-packages/aiogram/dispatcher/middlewares/user_context.py", line 27, in __call__
    return await handler(event, data)
  File "/home/zaur/Документы/turbo.az/Bina_Az_Bot/venv/lib/python3.10/site-packages/aiogram/fsm/middleware.py", line 41, in __call__
    return await handler(event, data)
  File "/home/zaur/Документы/turbo.az/Bina_Az_Bot/venv/lib/python3.10/site-packages/aiogram/dispatcher/event/telegram.py", line 120, in trigger
    return await wrapped_inner(event, kwargs)
  File "/home/zaur/Документы/turbo.az/Bina_Az_Bot/venv/lib/python3.10/site-packages/aiogram/dispatcher/event/handler.py", line 42, in call
    return await wrapped()
  File "/home/zaur/Документы/turbo.az/Bina_Az_Bot/venv/lib/python3.10/site-packages/aiogram/dispatcher/dispatcher.py", line 275, in _listen_update
    return await self.propagate_event(update_type=update_type, event=event, **kwargs)
  File "/home/zaur/Документы/turbo.az/Bina_Az_Bot/venv/lib/python3.10/site-packages/aiogram/dispatcher/router.py", line 116, in propagate_event
    return await observer.wrap_outer_middleware(_wrapped, event=event, data=kwargs)
  File "/home/zaur/Документы/turbo.az/Bina_Az_Bot/venv/lib/python3.10/site-packages/aiogram/dispatcher/router.py", line 111, in _wrapped
    return await self._propagate_event(
  File "/home/zaur/Документы/turbo.az/Bina_Az_Bot/venv/lib/python3.10/site-packages/aiogram/dispatcher/router.py", line 136, in _propagate_event
    response = await observer.trigger(event, **kwargs)
  File "/home/zaur/Документы/turbo.az/Bina_Az_Bot/venv/lib/python3.10/site-packages/aiogram/dispatcher/event/telegram.py", line 120, in trigger
    return await wrapped_inner(event, kwargs)
  File "/home/zaur/Документы/turbo.az/Bina_Az_Bot/venv/lib/python3.10/site-packages/aiogram/dispatcher/event/handler.py", line 42, in call
    return await wrapped()
  File "/home/zaur/Документы/turbo.az/Bina_Az_Bot/bot.py", line 18, in command_start_handler
    await message.answer(f"Привет, {hbold(message.from_user.full_name)}! Я бот Турбо.аз, и я помогу купить тебе машину твоей мечты!", reply_markup=keyboard)
UnboundLocalError: local variable 'keyboard' referenced before assignment
2023-10-01 12:58:45,933 - ERROR - Cause exception while process update id=613471223 by bot id=6113472397
ValidationError: 1 validation error for ReplyKeyboardMarkup
keyboard
  Field required [type=missing, input_value={'resize_keyboard': True}, input_type=dict]
    For further information visit https://errors.pydantic.dev/2.3/v/missing
Traceback (most recent call last):
  File "/home/zaur/Документы/turbo.az/Bina_Az_Bot/venv/lib/python3.10/site-packages/aiogram/dispatcher/dispatcher.py", line 308, in _process_update
    response = await self.feed_update(bot, update, **kwargs)
  File "/home/zaur/Документы/turbo.az/Bina_Az_Bot/venv/lib/python3.10/site-packages/aiogram/dispatcher/dispatcher.py", line 157, in feed_update
    response = await self.update.wrap_outer_middleware(
  File "/home/zaur/Документы/turbo.az/Bina_Az_Bot/venv/lib/python3.10/site-packages/aiogram/dispatcher/middlewares/error.py", line 25, in __call__
    return await handler(event, data)
  File "/home/zaur/Документы/turbo.az/Bina_Az_Bot/venv/lib/python3.10/site-packages/aiogram/dispatcher/middlewares/user_context.py", line 27, in __call__
    return await handler(event, data)
  File "/home/zaur/Документы/turbo.az/Bina_Az_Bot/venv/lib/python3.10/site-packages/aiogram/fsm/middleware.py", line 41, in __call__
    return await handler(event, data)
  File "/home/zaur/Документы/turbo.az/Bina_Az_Bot/venv/lib/python3.10/site-packages/aiogram/dispatcher/event/telegram.py", line 120, in trigger
    return await wrapped_inner(event, kwargs)
  File "/home/zaur/Документы/turbo.az/Bina_Az_Bot/venv/lib/python3.10/site-packages/aiogram/dispatcher/event/handler.py", line 42, in call
    return await wrapped()
  File "/home/zaur/Документы/turbo.az/Bina_Az_Bot/venv/lib/python3.10/site-packages/aiogram/dispatcher/dispatcher.py", line 275, in _listen_update
    return await self.propagate_event(update_type=update_type, event=event, **kwargs)
  File "/home/zaur/Документы/turbo.az/Bina_Az_Bot/venv/lib/python3.10/site-packages/aiogram/dispatcher/router.py", line 116, in propagate_event
    return await observer.wrap_outer_middleware(_wrapped, event=event, data=kwargs)
  File "/home/zaur/Документы/turbo.az/Bina_Az_Bot/venv/lib/python3.10/site-packages/aiogram/dispatcher/router.py", line 111, in _wrapped
    return await self._propagate_event(
  File "/home/zaur/Документы/turbo.az/Bina_Az_Bot/venv/lib/python3.10/site-packages/aiogram/dispatcher/router.py", line 136, in _propagate_event
    response = await observer.trigger(event, **kwargs)
  File "/home/zaur/Документы/turbo.az/Bina_Az_Bot/venv/lib/python3.10/site-packages/aiogram/dispatcher/event/telegram.py", line 120, in trigger
    return await wrapped_inner(event, kwargs)
  File "/home/zaur/Документы/turbo.az/Bina_Az_Bot/venv/lib/python3.10/site-packages/aiogram/dispatcher/event/handler.py", line 42, in call
    return await wrapped()
  File "/home/zaur/Документы/turbo.az/Bina_Az_Bot/bot.py", line 19, in command_start_handler
    keyboard = types.ReplyKeyboardMarkup(resize_keyboard=True)
  File "/home/zaur/Документы/turbo.az/Bina_Az_Bot/venv/lib/python3.10/site-packages/pydantic/main.py", line 165, in __init__
    __pydantic_self__.__pydantic_validator__.validate_python(data, self_instance=__pydantic_self__)
pydantic_core._pydantic_core.ValidationError: 1 validation error for ReplyKeyboardMarkup
keyboard
  Field required [type=missing, input_value={'resize_keyboard': True}, input_type=dict]
    For further information visit https://errors.pydantic.dev/2.3/v/missing
2023-10-01 13:00:56,966 - ERROR - Cause exception while process update id=613471228 by bot id=6113472397
ValidationError: 1 validation error for ReplyKeyboardMarkup
keyboard
  Field required [type=missing, input_value={'resize_keyboard': True}, input_type=dict]
    For further information visit https://errors.pydantic.dev/2.3/v/missing
Traceback (most recent call last):
  File "/home/zaur/Документы/turbo.az/Bina_Az_Bot/venv/lib/python3.10/site-packages/aiogram/dispatcher/dispatcher.py", line 308, in _process_update
    response = await self.feed_update(bot, update, **kwargs)
  File "/home/zaur/Документы/turbo.az/Bina_Az_Bot/venv/lib/python3.10/site-packages/aiogram/dispatcher/dispatcher.py", line 157, in feed_update
    response = await self.update.wrap_outer_middleware(
  File "/home/zaur/Документы/turbo.az/Bina_Az_Bot/venv/lib/python3.10/site-packages/aiogram/dispatcher/middlewares/error.py", line 25, in __call__
    return await handler(event, data)
  File "/home/zaur/Документы/turbo.az/Bina_Az_Bot/venv/lib/python3.10/site-packages/aiogram/dispatcher/middlewares/user_context.py", line 27, in __call__
    return await handler(event, data)
  File "/home/zaur/Документы/turbo.az/Bina_Az_Bot/venv/lib/python3.10/site-packages/aiogram/fsm/middleware.py", line 41, in __call__
    return await handler(event, data)
  File "/home/zaur/Документы/turbo.az/Bina_Az_Bot/venv/lib/python3.10/site-packages/aiogram/dispatcher/event/telegram.py", line 120, in trigger
    return await wrapped_inner(event, kwargs)
  File "/home/zaur/Документы/turbo.az/Bina_Az_Bot/venv/lib/python3.10/site-packages/aiogram/dispatcher/event/handler.py", line 42, in call
    return await wrapped()
  File "/home/zaur/Документы/turbo.az/Bina_Az_Bot/venv/lib/python3.10/site-packages/aiogram/dispatcher/dispatcher.py", line 275, in _listen_update
    return await self.propagate_event(update_type=update_type, event=event, **kwargs)
  File "/home/zaur/Документы/turbo.az/Bina_Az_Bot/venv/lib/python3.10/site-packages/aiogram/dispatcher/router.py", line 116, in propagate_event
    return await observer.wrap_outer_middleware(_wrapped, event=event, data=kwargs)
  File "/home/zaur/Документы/turbo.az/Bina_Az_Bot/venv/lib/python3.10/site-packages/aiogram/dispatcher/router.py", line 111, in _wrapped
    return await self._propagate_event(
  File "/home/zaur/Документы/turbo.az/Bina_Az_Bot/venv/lib/python3.10/site-packages/aiogram/dispatcher/router.py", line 136, in _propagate_event
    response = await observer.trigger(event, **kwargs)
  File "/home/zaur/Документы/turbo.az/Bina_Az_Bot/venv/lib/python3.10/site-packages/aiogram/dispatcher/event/telegram.py", line 120, in trigger
    return await wrapped_inner(event, kwargs)
  File "/home/zaur/Документы/turbo.az/Bina_Az_Bot/venv/lib/python3.10/site-packages/aiogram/dispatcher/event/handler.py", line 42, in call
    return await wrapped()
  File "/home/zaur/Документы/turbo.az/Bina_Az_Bot/bot.py", line 22, in command_start_handler
    keyboard = types.ReplyKeyboardMarkup(resize_keyboard=True)
  File "/home/zaur/Документы/turbo.az/Bina_Az_Bot/venv/lib/python3.10/site-packages/pydantic/main.py", line 165, in __init__
    __pydantic_self__.__pydantic_validator__.validate_python(data, self_instance=__pydantic_self__)
pydantic_core._pydantic_core.ValidationError: 1 validation error for ReplyKeyboardMarkup
keyboard
  Field required [type=missing, input_value={'resize_keyboard': True}, input_type=dict]
    For further information visit https://errors.pydantic.dev/2.3/v/missing
2023-10-01 13:13:16,115 - ERROR - Cause exception while process update id=613471229 by bot id=6113472397
ValidationError: 1 validation error for ReplyKeyboardMarkup
keyboard
  Field required [type=missing, input_value={}, input_type=dict]
    For further information visit https://errors.pydantic.dev/2.3/v/missing
Traceback (most recent call last):
  File "/home/zaur/Документы/turbo.az/Bina_Az_Bot/venv/lib/python3.10/site-packages/aiogram/dispatcher/dispatcher.py", line 308, in _process_update
    response = await self.feed_update(bot, update, **kwargs)
  File "/home/zaur/Документы/turbo.az/Bina_Az_Bot/venv/lib/python3.10/site-packages/aiogram/dispatcher/dispatcher.py", line 157, in feed_update
    response = await self.update.wrap_outer_middleware(
  File "/home/zaur/Документы/turbo.az/Bina_Az_Bot/venv/lib/python3.10/site-packages/aiogram/dispatcher/middlewares/error.py", line 25, in __call__
    return await handler(event, data)
  File "/home/zaur/Документы/turbo.az/Bina_Az_Bot/venv/lib/python3.10/site-packages/aiogram/dispatcher/middlewares/user_context.py", line 27, in __call__
    return await handler(event, data)
  File "/home/zaur/Документы/turbo.az/Bina_Az_Bot/venv/lib/python3.10/site-packages/aiogram/fsm/middleware.py", line 41, in __call__
    return await handler(event, data)
  File "/home/zaur/Документы/turbo.az/Bina_Az_Bot/venv/lib/python3.10/site-packages/aiogram/dispatcher/event/telegram.py", line 120, in trigger
    return await wrapped_inner(event, kwargs)
  File "/home/zaur/Документы/turbo.az/Bina_Az_Bot/venv/lib/python3.10/site-packages/aiogram/dispatcher/event/handler.py", line 42, in call
    return await wrapped()
  File "/home/zaur/Документы/turbo.az/Bina_Az_Bot/venv/lib/python3.10/site-packages/aiogram/dispatcher/dispatcher.py", line 275, in _listen_update
    return await self.propagate_event(update_type=update_type, event=event, **kwargs)
  File "/home/zaur/Документы/turbo.az/Bina_Az_Bot/venv/lib/python3.10/site-packages/aiogram/dispatcher/router.py", line 116, in propagate_event
    return await observer.wrap_outer_middleware(_wrapped, event=event, data=kwargs)
  File "/home/zaur/Документы/turbo.az/Bina_Az_Bot/venv/lib/python3.10/site-packages/aiogram/dispatcher/router.py", line 111, in _wrapped
    return await self._propagate_event(
  File "/home/zaur/Документы/turbo.az/Bina_Az_Bot/venv/lib/python3.10/site-packages/aiogram/dispatcher/router.py", line 136, in _propagate_event
    response = await observer.trigger(event, **kwargs)
  File "/home/zaur/Документы/turbo.az/Bina_Az_Bot/venv/lib/python3.10/site-packages/aiogram/dispatcher/event/telegram.py", line 120, in trigger
    return await wrapped_inner(event, kwargs)
  File "/home/zaur/Документы/turbo.az/Bina_Az_Bot/venv/lib/python3.10/site-packages/aiogram/dispatcher/event/handler.py", line 42, in call
    return await wrapped()
  File "/home/zaur/Документы/turbo.az/Bina_Az_Bot/bot.py", line 26, in command_start_handler
    keyboard = ReplyKeyboardMarkup()
  File "/home/zaur/Документы/turbo.az/Bina_Az_Bot/venv/lib/python3.10/site-packages/pydantic/main.py", line 165, in __init__
    __pydantic_self__.__pydantic_validator__.validate_python(data, self_instance=__pydantic_self__)
pydantic_core._pydantic_core.ValidationError: 1 validation error for ReplyKeyboardMarkup
keyboard
  Field required [type=missing, input_value={}, input_type=dict]
    For further information visit https://errors.pydantic.dev/2.3/v/missing
2023-10-01 13:30:43,175 - ERROR - Task was destroyed but it is pending!
task: <Task pending name='Task-1' coro=<scan_every_minute() running at /home/zaur/Документы/turbo.az/Bina_Az_Bot/bot.py:27>>
2023-10-01 13:32:33,948 - ERROR - Task was destroyed but it is pending!
task: <Task pending name='Task-1' coro=<scan_every_minute() running at /home/zaur/Документы/turbo.az/Bina_Az_Bot/bot.py:27>>
2023-10-01 14:25:36,101 - ERROR - Failed to fetch updates - TelegramNetworkError: HTTP Client says - Request timeout error
2023-10-01 14:26:15,728 - ERROR - Task was destroyed but it is pending!
task: <Task pending name='Task-1' coro=<scan_every_minute() running at /home/zaur/Документы/turbo.az/Bina_Az_Bot/bot.py:27>>
2023-10-01 14:26:15,728 - ERROR - Unclosed client session
client_session: <aiohttp.client.ClientSession object at 0x7f63f290d630>
2023-10-01 14:26:15,728 - ERROR - Unclosed connector
connections: ['[(<aiohttp.client_proto.ResponseHandler object at 0x7f63f292cf40>, 7681.340273746)]']
connector: <aiohttp.connector.TCPConnector object at 0x7f63f290d5a0>
2023-10-01 14:31:54,003 - ERROR - Task exception was never retrieved
future: <Task finished name='Task-1' coro=<scan_every_minute() done, defined at /home/zaur/Документы/turbo.az/Bina_Az_Bot/bot.py:21> exception=CantParseEntities("Can't parse entities: can't find end tag corresponding to start tag b")>
Traceback (most recent call last):
  File "/home/zaur/Документы/turbo.az/Bina_Az_Bot/bot.py", line 30, in scan_every_minute
    await bot.send_message(user_id,new_car, disable_notification=True)
  File "/home/zaur/Документы/turbo.az/Bina_Az_Bot/venv/lib/python3.10/site-packages/aiogram/bot/bot.py", line 219, in send_message
    result = await self.request(api.Methods.SEND_MESSAGE, payload)
  File "/home/zaur/Документы/turbo.az/Bina_Az_Bot/venv/lib/python3.10/site-packages/aiogram/bot/base.py", line 201, in request
    return await api.make_request(self.session, self.__token, method, data, files,
  File "/home/zaur/Документы/turbo.az/Bina_Az_Bot/venv/lib/python3.10/site-packages/aiogram/bot/api.py", line 104, in make_request
    return check_result(method, response.content_type, response.status, await response.text())
  File "/home/zaur/Документы/turbo.az/Bina_Az_Bot/venv/lib/python3.10/site-packages/aiogram/bot/api.py", line 78, in check_result
    exceptions.BadRequest.detect(description)
  File "/home/zaur/Документы/turbo.az/Bina_Az_Bot/venv/lib/python3.10/site-packages/aiogram/utils/exceptions.py", line 136, in detect
    raise err(cls.text or description)
aiogram.utils.exceptions.CantParseEntities: Can't parse entities: can't find end tag corresponding to start tag b
2023-10-01 14:35:04,724 - ERROR - Task exception was never retrieved
future: <Task finished name='Task-1' coro=<scan_every_minute() done, defined at /home/zaur/Документы/turbo.az/Bina_Az_Bot/bot.py:21> exception=CantParseEntities("Can't parse entities: can't find end tag corresponding to start tag b")>
Traceback (most recent call last):
  File "/home/zaur/Документы/turbo.az/Bina_Az_Bot/bot.py", line 30, in scan_every_minute
    await bot.send_message(user_id,new_car, disable_notification=True)
  File "/home/zaur/Документы/turbo.az/Bina_Az_Bot/venv/lib/python3.10/site-packages/aiogram/bot/bot.py", line 219, in send_message
    result = await self.request(api.Methods.SEND_MESSAGE, payload)
  File "/home/zaur/Документы/turbo.az/Bina_Az_Bot/venv/lib/python3.10/site-packages/aiogram/bot/base.py", line 201, in request
    return await api.make_request(self.session, self.__token, method, data, files,
  File "/home/zaur/Документы/turbo.az/Bina_Az_Bot/venv/lib/python3.10/site-packages/aiogram/bot/api.py", line 104, in make_request
    return check_result(method, response.content_type, response.status, await response.text())
  File "/home/zaur/Документы/turbo.az/Bina_Az_Bot/venv/lib/python3.10/site-packages/aiogram/bot/api.py", line 78, in check_result
    exceptions.BadRequest.detect(description)
  File "/home/zaur/Документы/turbo.az/Bina_Az_Bot/venv/lib/python3.10/site-packages/aiogram/utils/exceptions.py", line 136, in detect
    raise err(cls.text or description)
aiogram.utils.exceptions.CantParseEntities: Can't parse entities: can't find end tag corresponding to start tag b
2023-10-01 14:39:38,361 - ERROR - Task exception was never retrieved
future: <Task finished name='Task-1' coro=<scan_every_minute() done, defined at /home/zaur/Документы/turbo.az/Bina_Az_Bot/bot.py:21> exception=CantParseEntities("Can't parse entities: can't find end tag corresponding to start tag b")>
Traceback (most recent call last):
  File "/home/zaur/Документы/turbo.az/Bina_Az_Bot/bot.py", line 31, in scan_every_minute
    await bot.send_message(user_id, new_car, disable_notification=True)
  File "/home/zaur/Документы/turbo.az/Bina_Az_Bot/venv/lib/python3.10/site-packages/aiogram/bot/bot.py", line 219, in send_message
    result = await self.request(api.Methods.SEND_MESSAGE, payload)
  File "/home/zaur/Документы/turbo.az/Bina_Az_Bot/venv/lib/python3.10/site-packages/aiogram/bot/base.py", line 201, in request
    return await api.make_request(self.session, self.__token, method, data, files,
  File "/home/zaur/Документы/turbo.az/Bina_Az_Bot/venv/lib/python3.10/site-packages/aiogram/bot/api.py", line 104, in make_request
    return check_result(method, response.content_type, response.status, await response.text())
  File "/home/zaur/Документы/turbo.az/Bina_Az_Bot/venv/lib/python3.10/site-packages/aiogram/bot/api.py", line 78, in check_result
    exceptions.BadRequest.detect(description)
  File "/home/zaur/Документы/turbo.az/Bina_Az_Bot/venv/lib/python3.10/site-packages/aiogram/utils/exceptions.py", line 136, in detect
    raise err(cls.text or description)
aiogram.utils.exceptions.CantParseEntities: Can't parse entities: can't find end tag corresponding to start tag b
2023-10-01 14:43:16,630 - ERROR - Task exception was never retrieved
future: <Task finished name='Task-1' coro=<scan_every_minute() done, defined at /home/zaur/Документы/turbo.az/Bina_Az_Bot/bot.py:21> exception=CantParseEntities("Can't parse entities: can't find end tag corresponding to start tag b")>
Traceback (most recent call last):
  File "/home/zaur/Документы/turbo.az/Bina_Az_Bot/bot.py", line 31, in scan_every_minute
    await bot.send_message(user_id, new_car, disable_notification=True)
  File "/home/zaur/Документы/turbo.az/Bina_Az_Bot/venv/lib/python3.10/site-packages/aiogram/bot/bot.py", line 219, in send_message
    result = await self.request(api.Methods.SEND_MESSAGE, payload)
  File "/home/zaur/Документы/turbo.az/Bina_Az_Bot/venv/lib/python3.10/site-packages/aiogram/bot/base.py", line 201, in request
    return await api.make_request(self.session, self.__token, method, data, files,
  File "/home/zaur/Документы/turbo.az/Bina_Az_Bot/venv/lib/python3.10/site-packages/aiogram/bot/api.py", line 104, in make_request
    return check_result(method, response.content_type, response.status, await response.text())
  File "/home/zaur/Документы/turbo.az/Bina_Az_Bot/venv/lib/python3.10/site-packages/aiogram/bot/api.py", line 78, in check_result
    exceptions.BadRequest.detect(description)
  File "/home/zaur/Документы/turbo.az/Bina_Az_Bot/venv/lib/python3.10/site-packages/aiogram/utils/exceptions.py", line 136, in detect
    raise err(cls.text or description)
aiogram.utils.exceptions.CantParseEntities: Can't parse entities: can't find end tag corresponding to start tag b
2023-10-01 14:44:05,852 - ERROR - Task exception was never retrieved
future: <Task finished name='Task-1' coro=<scan_every_minute() done, defined at /home/zaur/Документы/turbo.az/Bina_Az_Bot/bot.py:21> exception=CantParseEntities("Can't parse entities: can't find end tag corresponding to start tag b")>
Traceback (most recent call last):
  File "/home/zaur/Документы/turbo.az/Bina_Az_Bot/bot.py", line 31, in scan_every_minute
    await bot.send_message(user_id, new_car, disable_notification=True)
  File "/home/zaur/Документы/turbo.az/Bina_Az_Bot/venv/lib/python3.10/site-packages/aiogram/bot/bot.py", line 219, in send_message
    result = await self.request(api.Methods.SEND_MESSAGE, payload)
  File "/home/zaur/Документы/turbo.az/Bina_Az_Bot/venv/lib/python3.10/site-packages/aiogram/bot/base.py", line 201, in request
    return await api.make_request(self.session, self.__token, method, data, files,
  File "/home/zaur/Документы/turbo.az/Bina_Az_Bot/venv/lib/python3.10/site-packages/aiogram/bot/api.py", line 104, in make_request
    return check_result(method, response.content_type, response.status, await response.text())
  File "/home/zaur/Документы/turbo.az/Bina_Az_Bot/venv/lib/python3.10/site-packages/aiogram/bot/api.py", line 78, in check_result
    exceptions.BadRequest.detect(description)
  File "/home/zaur/Документы/turbo.az/Bina_Az_Bot/venv/lib/python3.10/site-packages/aiogram/utils/exceptions.py", line 136, in detect
    raise err(cls.text or description)
aiogram.utils.exceptions.CantParseEntities: Can't parse entities: can't find end tag corresponding to start tag b
2023-10-01 14:49:28,755 - ERROR - Task exception was never retrieved
future: <Task finished name='Task-1' coro=<scan_every_minute() done, defined at /home/zaur/Документы/turbo.az/Bina_Az_Bot/bot.py:21> exception=CantParseEntities("Can't parse entities: can't find end tag corresponding to start tag b")>
Traceback (most recent call last):
  File "/home/zaur/Документы/turbo.az/Bina_Az_Bot/bot.py", line 31, in scan_every_minute
    await bot.send_message(user_id, new_car, disable_notification=True)
  File "/home/zaur/Документы/turbo.az/Bina_Az_Bot/venv/lib/python3.10/site-packages/aiogram/bot/bot.py", line 219, in send_message
    result = await self.request(api.Methods.SEND_MESSAGE, payload)
  File "/home/zaur/Документы/turbo.az/Bina_Az_Bot/venv/lib/python3.10/site-packages/aiogram/bot/base.py", line 201, in request
    return await api.make_request(self.session, self.__token, method, data, files,
  File "/home/zaur/Документы/turbo.az/Bina_Az_Bot/venv/lib/python3.10/site-packages/aiogram/bot/api.py", line 104, in make_request
    return check_result(method, response.content_type, response.status, await response.text())
  File "/home/zaur/Документы/turbo.az/Bina_Az_Bot/venv/lib/python3.10/site-packages/aiogram/bot/api.py", line 78, in check_result
    exceptions.BadRequest.detect(description)
  File "/home/zaur/Документы/turbo.az/Bina_Az_Bot/venv/lib/python3.10/site-packages/aiogram/utils/exceptions.py", line 136, in detect
    raise err(cls.text or description)
aiogram.utils.exceptions.CantParseEntities: Can't parse entities: can't find end tag corresponding to start tag b
2023-10-01 14:51:15,633 - ERROR - Task exception was never retrieved
future: <Task finished name='Task-1' coro=<scan_every_minute() done, defined at /home/zaur/Документы/turbo.az/Bina_Az_Bot/bot.py:21> exception=CantParseEntities("Can't parse entities: can't find end tag corresponding to start tag b")>
Traceback (most recent call last):
  File "/home/zaur/Документы/turbo.az/Bina_Az_Bot/bot.py", line 33, in scan_every_minute
    await bot.send_message(user_id, new_car, disable_notification=True)
  File "/home/zaur/Документы/turbo.az/Bina_Az_Bot/venv/lib/python3.10/site-packages/aiogram/bot/bot.py", line 219, in send_message
    result = await self.request(api.Methods.SEND_MESSAGE, payload)
  File "/home/zaur/Документы/turbo.az/Bina_Az_Bot/venv/lib/python3.10/site-packages/aiogram/bot/base.py", line 201, in request
    return await api.make_request(self.session, self.__token, method, data, files,
  File "/home/zaur/Документы/turbo.az/Bina_Az_Bot/venv/lib/python3.10/site-packages/aiogram/bot/api.py", line 104, in make_request
    return check_result(method, response.content_type, response.status, await response.text())
  File "/home/zaur/Документы/turbo.az/Bina_Az_Bot/venv/lib/python3.10/site-packages/aiogram/bot/api.py", line 78, in check_result
    exceptions.BadRequest.detect(description)
  File "/home/zaur/Документы/turbo.az/Bina_Az_Bot/venv/lib/python3.10/site-packages/aiogram/utils/exceptions.py", line 136, in detect
    raise err(cls.text or description)
aiogram.utils.exceptions.CantParseEntities: Can't parse entities: can't find end tag corresponding to start tag b
2023-10-01 14:52:51,898 - ERROR - Task exception was never retrieved
future: <Task finished name='Task-1' coro=<scan_every_minute() done, defined at /home/zaur/Документы/turbo.az/Bina_Az_Bot/bot.py:21> exception=CantParseEntities("Can't parse entities: can't find end tag corresponding to start tag b")>
Traceback (most recent call last):
  File "/home/zaur/Документы/turbo.az/Bina_Az_Bot/bot.py", line 33, in scan_every_minute
    await bot.send_message(user_id, new_car, disable_notification=True)
  File "/home/zaur/Документы/turbo.az/Bina_Az_Bot/venv/lib/python3.10/site-packages/aiogram/bot/bot.py", line 219, in send_message
    result = await self.request(api.Methods.SEND_MESSAGE, payload)
  File "/home/zaur/Документы/turbo.az/Bina_Az_Bot/venv/lib/python3.10/site-packages/aiogram/bot/base.py", line 201, in request
    return await api.make_request(self.session, self.__token, method, data, files,
  File "/home/zaur/Документы/turbo.az/Bina_Az_Bot/venv/lib/python3.10/site-packages/aiogram/bot/api.py", line 104, in make_request
    return check_result(method, response.content_type, response.status, await response.text())
  File "/home/zaur/Документы/turbo.az/Bina_Az_Bot/venv/lib/python3.10/site-packages/aiogram/bot/api.py", line 78, in check_result
    exceptions.BadRequest.detect(description)
  File "/home/zaur/Документы/turbo.az/Bina_Az_Bot/venv/lib/python3.10/site-packages/aiogram/utils/exceptions.py", line 136, in detect
    raise err(cls.text or description)
aiogram.utils.exceptions.CantParseEntities: Can't parse entities: can't find end tag corresponding to start tag b
2023-10-01 15:13:24,165 - ERROR - Task exception was never retrieved
future: <Task finished name='Task-1' coro=<scan_every_minute() done, defined at /home/zaur/Документы/turbo.az/Bina_Az_Bot/bot.py:49> exception=KeyboardInterrupt()>
Traceback (most recent call last):
  File "/home/zaur/Документы/turbo.az/Bina_Az_Bot/venv/lib/python3.10/site-packages/aiogram/utils/executor.py", line 308, in start_polling
    loop.run_forever()
  File "/usr/lib/python3.10/asyncio/base_events.py", line 603, in run_forever
    self._run_once()
  File "/usr/lib/python3.10/asyncio/base_events.py", line 1909, in _run_once
    handle._run()
  File "/usr/lib/python3.10/asyncio/events.py", line 80, in _run
    self._context.run(self._callback, *self._args)
  File "/home/zaur/Документы/turbo.az/Bina_Az_Bot/bot.py", line 51, in scan_every_minute
    fresh_cars = get_car()
  File "/home/zaur/Документы/turbo.az/Bina_Az_Bot/parser.py", line 23, in get_car
    r = requests.get(url=url, headers=headers)
  File "/home/zaur/Документы/turbo.az/Bina_Az_Bot/venv/lib/python3.10/site-packages/requests/api.py", line 73, in get
    return request("get", url, params=params, **kwargs)
  File "/home/zaur/Документы/turbo.az/Bina_Az_Bot/venv/lib/python3.10/site-packages/requests/api.py", line 59, in request
    return session.request(method=method, url=url, **kwargs)
  File "/home/zaur/Документы/turbo.az/Bina_Az_Bot/venv/lib/python3.10/site-packages/requests/sessions.py", line 589, in request
    resp = self.send(prep, **send_kwargs)
  File "/home/zaur/Документы/turbo.az/Bina_Az_Bot/venv/lib/python3.10/site-packages/requests/sessions.py", line 703, in send
    r = adapter.send(request, **kwargs)
  File "/home/zaur/Документы/turbo.az/Bina_Az_Bot/venv/lib/python3.10/site-packages/requests/adapters.py", line 486, in send
    resp = conn.urlopen(
  File "/home/zaur/Документы/turbo.az/Bina_Az_Bot/venv/lib/python3.10/site-packages/urllib3/connectionpool.py", line 790, in urlopen
    response = self._make_request(
  File "/home/zaur/Документы/turbo.az/Bina_Az_Bot/venv/lib/python3.10/site-packages/urllib3/connectionpool.py", line 536, in _make_request
    response = conn.getresponse()
  File "/home/zaur/Документы/turbo.az/Bina_Az_Bot/venv/lib/python3.10/site-packages/urllib3/connection.py", line 461, in getresponse
    httplib_response = super().getresponse()
  File "/usr/lib/python3.10/http/client.py", line 1375, in getresponse
    response.begin()
  File "/usr/lib/python3.10/http/client.py", line 318, in begin
    version, status, reason = self._read_status()
  File "/usr/lib/python3.10/http/client.py", line 279, in _read_status
    line = str(self.fp.readline(_MAXLINE + 1), "iso-8859-1")
  File "/usr/lib/python3.10/socket.py", line 705, in readinto
    return self._sock.recv_into(b)
  File "/usr/lib/python3.10/ssl.py", line 1274, in recv_into
    return self.read(nbytes, buffer)
  File "/usr/lib/python3.10/ssl.py", line 1130, in read
    return self._sslobj.read(len, buffer)
KeyboardInterrupt
2023-10-01 15:46:46,481 - ERROR - Ошибка при отправке файла bot_errors.log: [Errno 2] No such file or directory: 'bot_errors.log'
